<?xml version="1.0" encoding="utf-8"?>
<mujoco model="mirobot_urdf"  xmlns:xacro="http://www.ros.org/wiki/xacro">
  
  <xacro:arg name="control_rate" default="500"/>

  <xacro:property name="control_rate"     value="$(arg control_rate)"/>
  <xacro:property name="control_timestep" value="${1 / control_rate}"/>

  <xacro:property name="timestep"            value="${control_timestep / 10}"/>
  <xacro:property name="error_timestep"      value="${control_timestep / 2}"/>
  <xacro:property name="compliance_timestep" value="${control_timestep * 10}"/>

  <xacro:property name="world_congroup"       value="0"/>
  <xacro:property name="robot_congroup"       value="1"/>
  <xacro:property name="endeffector_congroup" value="2"/>

  <compiler angle="radian" autolimits="true" />
  <option timestep="${timestep}" />

  <default class="main">

    <equality solref="${error_timestep} 1" />
    <geom solref="${error_timestep} 1" contype="${2**world_congroup}" conaffinity="${2**world_congroup}"/>

    <default class="tcp_compliance">
      <equality solref="${compliance_timestep} 1" />
    </default>

    <default class="robot">
      <geom contype="${2**robot_congroup}" conaffinity="${2**world_congroup}"/>
    </default>

    <default class="endeffector">
      <geom contype="${2**endeffector_congroup}" conaffinity="${2**world_congroup}"/>
    </default>

  </default>

  <statistic meansize="0.0683645" extent="0.410433" center="0.170127 0.0599294 0.136871" />

  <asset>
    <mesh name="base_link_collision" file="$(find mirobot_urdf)/meshes/base_link_collision.STL" />
    <mesh name="link1_collision"     file="$(find mirobot_urdf)/meshes/link1_collision.STL" />
    <mesh name="link2_collision"     file="$(find mirobot_urdf)/meshes/link2_collision.STL" />
    <mesh name="link3_collision"     file="$(find mirobot_urdf)/meshes/link3_collision.STL" />
    <mesh name="link4_collision"     file="$(find mirobot_urdf)/meshes/link4_collision.STL" />
    <mesh name="link5_collision"     file="$(find mirobot_urdf)/meshes/link5_collision.STL" />
    <mesh name="link6_collision"     file="$(find mirobot_urdf)/meshes/link6_collision.STL" />
    <mesh name="link61"              file="$(find mirobot_urdf)/meshes/link61.STL" />
  </asset>

  <worldbody>
    <!-- ROBOT ARM -->
    <body name="base" pos="0 0 0" gravcomp="1" childclass="robot">
      <body name="base_link" pos="0 0 0" gravcomp="1">
        <inertial pos="0 0 0.0295631" quat="0.5 0.5 -0.5 0.5" mass="0.83046" diaginertia="0.00181346 0.00122515 0.00122515" />
        <geom type="mesh" rgba="0.478431 0.478431 0.478431 1" mesh="base_link_collision" />

        <body name="link1" pos="0 0 0.08907" gravcomp="1">
          <inertial pos="0.0139205 0.000175676 0.0278205" quat="0.63697 0.301503 0.306394 0.639912" mass="0.100784" diaginertia="6.20698e-05 5.14973e-05 2.49373e-05" />
          <joint name="Joint1" pos="0 0 0" axis="0 0 1" range="-1.919 2.792" />
          <geom type="mesh" rgba="0.792157 0.819608 0.933333 1" mesh="link1_collision" />

          <body name="link2" pos="0.026689 -0.01 0.037919" gravcomp="1">
            <inertial pos="-0.000285886 -0.0166553 0.0497577" quat="0.707123 -0.0011095 -0.00125416 0.707089" mass="0.132171" diaginertia="0.000225757 0.000214472 2.33029e-05" />
            <joint name="Joint2" pos="0 0 0" axis="0 1 0" range="-0.611 1.222" />
            <geom type="mesh" rgba="1 0.6 0.247059 1" mesh="link2_collision" />

            <body name="link3" pos="-0.00052147 0 0.10356" gravcomp="1">
              <inertial pos="0.0158955 0.0218157 0.00468223" quat="0.0042885 0.613846 -0.00270477 0.78941" mass="0.0999859" diaginertia="0.000128775 0.000119394 2.89671e-05" />
              <joint name="Joint3" pos="0 0 0" axis="0 1 0" range="-2.094 1.047" />
              <geom type="mesh" rgba="0.792157 0.819608 0.933333 1" mesh="link3_collision" />

              <body name="link4" pos="0.11123 0.021295 0.019995" gravcomp="1">
                <inertial pos="0.0397448 -3.52691e-07 8.51159e-07" quat="-1.72755e-05 0.70712 1.30532e-05 0.707094" mass="0.0455777" diaginertia="2.34679e-05 1.74414e-05 1.02362e-05" />
                <joint name="Joint4" pos="0 0 0" axis="-1 0 0" range="-3.142 3.142" />
                <geom type="mesh" rgba="1 0.6 0.247059 1" mesh="link4_collision" />

                <body name="link5" pos="0.05775 0.006295 0" quat="-3.67321e-06 1 0 0" gravcomp="1">
                  <inertial pos="0 0.006295 0.00755281" quat="1 1.17491e-05 0 0" mass="0.0143828" diaginertia="1.94302e-06 1.83053e-06 1.09304e-06" />
                  <joint name="Joint5" pos="0 0 0" axis="0 -1 0" range="-3.49 0.523" />
                  <geom type="mesh" rgba="0.792157 0.819608 0.933333 1" mesh="link5_collision" />

                  <body name="link6" pos="0 0.0062949 0.019304" quat="-3.67321e-06 1 0 0" gravcomp="1">
                    <joint name="Joint6" pos="0 0 0" axis="0 2.7322e-05 1" range="-6.283 6.283" />
                    <geom type="cylinder" size="0.001 0.001" mass="0.001"/>

                  </body>
                </body>
              </body>
            </body>
          </body>
        </body>
      </body>
    </body>

    <!-- END-EFFECTOR -->
    <body name="link6_mocap" mocap="true"/>
    <body name="link6_dummy" childclass="endeffector">
      <freejoint/>
      <body name="link6_compliant" gravcomp="0">
        <inertial pos="0.0204857 -3.59449e-07 -0.0175089" quat="0.479509 0.519656 0.52003 0.479164" mass="0.0381324" diaginertia="2.62395e-05 2.61171e-05 3.3979e-06" />
        <geom quat="1.76037e-12 1.32679e-06 1 1.32679e-06" type="mesh" rgba="1 1 1 1" mesh="link6_collision" />
        <site name="ft_sensorsite"/>

        <body name="link61" pos="-0.046 0 -0.016" quat="-2.59734e-06 0.707105 -2.59735e-06 -0.707108">
          <inertial pos="0.005 1.36612e-07 -0.106942" quat="0.5 0.5 -0.5 0.5" mass="0.112187" diaginertia="1.55382e-05 1.05678e-05 1.05678e-05" />
          <geom type="mesh" rgba="1 1 1 1" mesh="link61" />

          <body name="imu_frame" pos="0 0 -0.11">
            <site name="imu_sensorsite" />

          </body>
        </body>
      </body>
    </body>

    <!-- MISC -->
    <light pos="0 0 1000" castshadow="true" />

  </worldbody>

  <!-- EQUALITY constraints -->
  <equality>
    <weld body1="link6_mocap" body2="link6_dummy" class="tcp_compliance" relpose="0 0 0 0 0 0 0"/>
  </equality>

  <!-- SENSORS -->
  <sensor>
    <force  name="force"  site="ft_sensorsite"/>
    <torque name="torque" site="ft_sensorsite"/>

    <framequat     name="quat"   objtype="site" objname="imu_sensorsite"/>
    <gyro          name="angvel" site="imu_sensorsite"/>
    <accelerometer name="linacc" site="imu_sensorsite"/>
  </sensor>

  <!-- Define a grouping of sensors that correspond to geometry_msgs/Wrench -->
  <custom>
    <tuple name="wrench">
      <element objname="wrench_sensor" objtype="tuple"/>
    </tuple>

    <tuple name="wrench_sensor">
      <element objname="force"  objtype="sensor"/>
      <element objname="torque" objtype="sensor"/>
    </tuple>
  </custom>

  <!-- Define a grouping of sensors that correspond to sensor_msgs/Imu -->
  <custom>
    <tuple name="imu">
      <element objname="imu_sensor" objtype="tuple"/>
    </tuple>

    <tuple name="imu_sensor">
      <element objname="quat"   objtype="sensor"/>
      <element objname="angvel" objtype="sensor"/>
      <element objname="linacc" objtype="sensor"/>
    </tuple>
  </custom>

</mujoco>